[2023-10-13T17:07:52.988+0000] {taskinstance.py:1157} INFO - Dependencies all met for dep_context=non-requeueable deps ti=<TaskInstance: pythonoperator.hello_with_python manual__2023-10-13T17:07:50.956717+00:00 [queued]>
[2023-10-13T17:07:52.996+0000] {taskinstance.py:1157} INFO - Dependencies all met for dep_context=requeueable deps ti=<TaskInstance: pythonoperator.hello_with_python manual__2023-10-13T17:07:50.956717+00:00 [queued]>
[2023-10-13T17:07:52.997+0000] {taskinstance.py:1359} INFO - Starting attempt 1 of 1
[2023-10-13T17:07:53.178+0000] {taskinstance.py:1380} INFO - Executing <Task(PythonOperator): hello_with_python> on 2023-10-13 17:07:50.956717+00:00
[2023-10-13T17:07:53.184+0000] {standard_task_runner.py:57} INFO - Started process 182 to run task
[2023-10-13T17:07:53.189+0000] {standard_task_runner.py:84} INFO - Running: ['***', 'tasks', 'run', 'pythonoperator', 'hello_with_python', 'manual__2023-10-13T17:07:50.956717+00:00', '--job-id', '18', '--raw', '--subdir', 'DAGS_FOLDER/pythonoperator.py', '--cfg-path', '/tmp/tmpf_vnmpao']
[2023-10-13T17:07:53.193+0000] {standard_task_runner.py:85} INFO - Job 18: Subtask hello_with_python
[2023-10-13T17:07:53.497+0000] {task_command.py:415} INFO - Running <TaskInstance: pythonoperator.hello_with_python manual__2023-10-13T17:07:50.956717+00:00 [running]> on host 1b178939b33f
[2023-10-13T17:07:53.648+0000] {taskinstance.py:1660} INFO - Exporting env vars: AIRFLOW_CTX_DAG_OWNER='***' AIRFLOW_CTX_DAG_ID='pythonoperator' AIRFLOW_CTX_TASK_ID='hello_with_python' AIRFLOW_CTX_EXECUTION_DATE='2023-10-13T17:07:50.956717+00:00' AIRFLOW_CTX_TRY_NUMBER='1' AIRFLOW_CTX_DAG_RUN_ID='manual__2023-10-13T17:07:50.956717+00:00'
[2023-10-13T17:07:53.650+0000] {logging_mixin.py:151} INFO - Hola moderfucker
[2023-10-13T17:07:53.653+0000] {taskinstance.py:1935} ERROR - Task failed with exception
Traceback (most recent call last):
  File "/home/airflow/.local/lib/python3.8/site-packages/airflow/operators/python.py", line 192, in execute
    return_value = self.execute_callable()
  File "/home/airflow/.local/lib/python3.8/site-packages/airflow/operators/python.py", line 209, in execute_callable
    return self.python_callable(*self.op_args, **self.op_kwargs)
  File "/opt/airflow/dags/pythonoperator.py", line 9, in print_hello
    spotify_df = pd.read_csv("spotify_dataset.csv")
  File "/home/airflow/.local/lib/python3.8/site-packages/pandas/io/parsers/readers.py", line 912, in read_csv
    return _read(filepath_or_buffer, kwds)
  File "/home/airflow/.local/lib/python3.8/site-packages/pandas/io/parsers/readers.py", line 577, in _read
    parser = TextFileReader(filepath_or_buffer, **kwds)
  File "/home/airflow/.local/lib/python3.8/site-packages/pandas/io/parsers/readers.py", line 1407, in __init__
    self._engine = self._make_engine(f, self.engine)
  File "/home/airflow/.local/lib/python3.8/site-packages/pandas/io/parsers/readers.py", line 1661, in _make_engine
    self.handles = get_handle(
  File "/home/airflow/.local/lib/python3.8/site-packages/pandas/io/common.py", line 859, in get_handle
    handle = open(
FileNotFoundError: [Errno 2] No such file or directory: 'spotify_dataset.csv'
[2023-10-13T17:07:53.668+0000] {taskinstance.py:1398} INFO - Marking task as FAILED. dag_id=pythonoperator, task_id=hello_with_python, execution_date=20231013T170750, start_date=20231013T170752, end_date=20231013T170753
[2023-10-13T17:07:53.849+0000] {standard_task_runner.py:104} ERROR - Failed to execute job 18 for task hello_with_python ([Errno 2] No such file or directory: 'spotify_dataset.csv'; 182)
[2023-10-13T17:07:53.884+0000] {local_task_job_runner.py:228} INFO - Task exited with return code 1
[2023-10-13T17:07:53.902+0000] {taskinstance.py:2776} INFO - 0 downstream tasks scheduled from follow-on schedule check
