[2023-10-14T04:51:44.242+0000] {processor.py:157} INFO - Started process (PID=36) to work on /opt/airflow/dags/bd.py
[2023-10-14T04:51:44.243+0000] {processor.py:829} INFO - Processing file /opt/airflow/dags/bd.py for tasks to queue
[2023-10-14T04:51:44.245+0000] {logging_mixin.py:151} INFO - [2023-10-14T04:51:44.245+0000] {dagbag.py:539} INFO - Filling up the DagBag from /opt/airflow/dags/bd.py
[2023-10-14T04:51:46.979+0000] {logging_mixin.py:151} INFO - Error al conectar a la base de datos: connection to server at "localhost" (127.0.0.1), port 5432 failed: Connection refused
	Is the server running on that host and accepting TCP/IP connections?
connection to server at "localhost" (::1), port 5432 failed: Cannot assign requested address
	Is the server running on that host and accepting TCP/IP connections?
[2023-10-14T04:51:46.988+0000] {logging_mixin.py:151} INFO - Error al ejecutar la consulta: name 'connection' is not defined
[2023-10-14T04:51:47.002+0000] {logging_mixin.py:151} INFO - [2023-10-14T04:51:46.989+0000] {dagbag.py:347} ERROR - Failed to import: /opt/airflow/dags/bd.py
Traceback (most recent call last):
  File "/home/airflow/.local/lib/python3.8/site-packages/airflow/models/dagbag.py", line 343, in parse
    loader.exec_module(new_module)
  File "<frozen importlib._bootstrap_external>", line 843, in exec_module
  File "<frozen importlib._bootstrap>", line 219, in _call_with_frames_removed
  File "/opt/airflow/dags/bd.py", line 123, in <module>
    if connection:
NameError: name 'connection' is not defined
[2023-10-14T04:51:47.006+0000] {processor.py:841} WARNING - No viable dags retrieved from /opt/airflow/dags/bd.py
[2023-10-14T04:51:47.070+0000] {processor.py:179} INFO - Processing /opt/airflow/dags/bd.py took 2.834 seconds
[2023-10-14T04:52:17.377+0000] {processor.py:157} INFO - Started process (PID=51) to work on /opt/airflow/dags/bd.py
[2023-10-14T04:52:17.379+0000] {processor.py:829} INFO - Processing file /opt/airflow/dags/bd.py for tasks to queue
[2023-10-14T04:52:17.381+0000] {logging_mixin.py:151} INFO - [2023-10-14T04:52:17.381+0000] {dagbag.py:539} INFO - Filling up the DagBag from /opt/airflow/dags/bd.py
[2023-10-14T04:52:19.465+0000] {logging_mixin.py:151} INFO - Error al conectar a la base de datos: connection to server at "localhost" (127.0.0.1), port 5432 failed: Connection refused
	Is the server running on that host and accepting TCP/IP connections?
connection to server at "localhost" (::1), port 5432 failed: Cannot assign requested address
	Is the server running on that host and accepting TCP/IP connections?
[2023-10-14T04:52:19.466+0000] {logging_mixin.py:151} INFO - Error al ejecutar la consulta: name 'connection' is not defined
[2023-10-14T04:52:19.495+0000] {logging_mixin.py:151} INFO - [2023-10-14T04:52:19.469+0000] {dagbag.py:347} ERROR - Failed to import: /opt/airflow/dags/bd.py
Traceback (most recent call last):
  File "/home/airflow/.local/lib/python3.8/site-packages/airflow/models/dagbag.py", line 343, in parse
    loader.exec_module(new_module)
  File "<frozen importlib._bootstrap_external>", line 843, in exec_module
  File "<frozen importlib._bootstrap>", line 219, in _call_with_frames_removed
  File "/opt/airflow/dags/bd.py", line 123, in <module>
    if connection:
NameError: name 'connection' is not defined
[2023-10-14T04:52:19.501+0000] {processor.py:841} WARNING - No viable dags retrieved from /opt/airflow/dags/bd.py
[2023-10-14T04:52:19.680+0000] {processor.py:179} INFO - Processing /opt/airflow/dags/bd.py took 2.309 seconds
[2023-10-14T04:52:55.434+0000] {processor.py:157} INFO - Started process (PID=65) to work on /opt/airflow/dags/bd.py
[2023-10-14T04:52:55.535+0000] {processor.py:829} INFO - Processing file /opt/airflow/dags/bd.py for tasks to queue
[2023-10-14T04:52:55.562+0000] {logging_mixin.py:151} INFO - [2023-10-14T04:52:55.561+0000] {dagbag.py:539} INFO - Filling up the DagBag from /opt/airflow/dags/bd.py
[2023-10-14T04:53:05.090+0000] {logging_mixin.py:151} INFO - Error al conectar a la base de datos: connection to server at "localhost" (127.0.0.1), port 5432 failed: Connection refused
	Is the server running on that host and accepting TCP/IP connections?
connection to server at "localhost" (::1), port 5432 failed: Cannot assign requested address
	Is the server running on that host and accepting TCP/IP connections?
[2023-10-14T04:53:05.093+0000] {logging_mixin.py:151} INFO - Error al ejecutar la consulta: name 'connection' is not defined
[2023-10-14T04:53:05.232+0000] {logging_mixin.py:151} INFO - [2023-10-14T04:53:05.097+0000] {dagbag.py:347} ERROR - Failed to import: /opt/airflow/dags/bd.py
Traceback (most recent call last):
  File "/home/airflow/.local/lib/python3.8/site-packages/airflow/models/dagbag.py", line 343, in parse
    loader.exec_module(new_module)
  File "<frozen importlib._bootstrap_external>", line 843, in exec_module
  File "<frozen importlib._bootstrap>", line 219, in _call_with_frames_removed
  File "/opt/airflow/dags/bd.py", line 123, in <module>
    if connection:
NameError: name 'connection' is not defined
[2023-10-14T04:53:05.248+0000] {processor.py:841} WARNING - No viable dags retrieved from /opt/airflow/dags/bd.py
[2023-10-14T04:53:05.544+0000] {processor.py:179} INFO - Processing /opt/airflow/dags/bd.py took 10.050 seconds
[2023-10-14T04:53:36.027+0000] {processor.py:157} INFO - Started process (PID=86) to work on /opt/airflow/dags/bd.py
[2023-10-14T04:53:36.028+0000] {processor.py:829} INFO - Processing file /opt/airflow/dags/bd.py for tasks to queue
[2023-10-14T04:53:36.031+0000] {logging_mixin.py:151} INFO - [2023-10-14T04:53:36.030+0000] {dagbag.py:539} INFO - Filling up the DagBag from /opt/airflow/dags/bd.py
[2023-10-14T04:53:36.896+0000] {logging_mixin.py:151} INFO - Error al conectar a la base de datos: connection to server at "localhost" (127.0.0.1), port 5432 failed: Connection refused
	Is the server running on that host and accepting TCP/IP connections?
connection to server at "localhost" (::1), port 5432 failed: Cannot assign requested address
	Is the server running on that host and accepting TCP/IP connections?
[2023-10-14T04:53:36.897+0000] {logging_mixin.py:151} INFO - Error al ejecutar la consulta: name 'connection' is not defined
[2023-10-14T04:53:36.909+0000] {logging_mixin.py:151} INFO - [2023-10-14T04:53:36.898+0000] {dagbag.py:347} ERROR - Failed to import: /opt/airflow/dags/bd.py
Traceback (most recent call last):
  File "/home/airflow/.local/lib/python3.8/site-packages/airflow/models/dagbag.py", line 343, in parse
    loader.exec_module(new_module)
  File "<frozen importlib._bootstrap_external>", line 843, in exec_module
  File "<frozen importlib._bootstrap>", line 219, in _call_with_frames_removed
  File "/opt/airflow/dags/bd.py", line 123, in <module>
    if connection:
NameError: name 'connection' is not defined
[2023-10-14T04:53:36.912+0000] {processor.py:841} WARNING - No viable dags retrieved from /opt/airflow/dags/bd.py
[2023-10-14T04:53:36.954+0000] {processor.py:179} INFO - Processing /opt/airflow/dags/bd.py took 0.935 seconds
[2023-10-14T04:54:07.404+0000] {processor.py:157} INFO - Started process (PID=100) to work on /opt/airflow/dags/bd.py
[2023-10-14T04:54:07.406+0000] {processor.py:829} INFO - Processing file /opt/airflow/dags/bd.py for tasks to queue
[2023-10-14T04:54:07.408+0000] {logging_mixin.py:151} INFO - [2023-10-14T04:54:07.407+0000] {dagbag.py:539} INFO - Filling up the DagBag from /opt/airflow/dags/bd.py
[2023-10-14T04:54:08.067+0000] {logging_mixin.py:151} INFO - Error al conectar a la base de datos: connection to server at "localhost" (127.0.0.1), port 5432 failed: Connection refused
	Is the server running on that host and accepting TCP/IP connections?
connection to server at "localhost" (::1), port 5432 failed: Cannot assign requested address
	Is the server running on that host and accepting TCP/IP connections?
[2023-10-14T04:54:08.069+0000] {logging_mixin.py:151} INFO - Error al ejecutar la consulta: name 'connection' is not defined
[2023-10-14T04:54:08.080+0000] {logging_mixin.py:151} INFO - [2023-10-14T04:54:08.070+0000] {dagbag.py:347} ERROR - Failed to import: /opt/airflow/dags/bd.py
Traceback (most recent call last):
  File "/home/airflow/.local/lib/python3.8/site-packages/airflow/models/dagbag.py", line 343, in parse
    loader.exec_module(new_module)
  File "<frozen importlib._bootstrap_external>", line 843, in exec_module
  File "<frozen importlib._bootstrap>", line 219, in _call_with_frames_removed
  File "/opt/airflow/dags/bd.py", line 123, in <module>
    if connection:
NameError: name 'connection' is not defined
[2023-10-14T04:54:08.083+0000] {processor.py:841} WARNING - No viable dags retrieved from /opt/airflow/dags/bd.py
[2023-10-14T04:54:08.164+0000] {processor.py:179} INFO - Processing /opt/airflow/dags/bd.py took 0.767 seconds
[2023-10-14T04:54:38.925+0000] {processor.py:157} INFO - Started process (PID=114) to work on /opt/airflow/dags/bd.py
[2023-10-14T04:54:38.931+0000] {processor.py:829} INFO - Processing file /opt/airflow/dags/bd.py for tasks to queue
[2023-10-14T04:54:38.933+0000] {logging_mixin.py:151} INFO - [2023-10-14T04:54:38.932+0000] {dagbag.py:539} INFO - Filling up the DagBag from /opt/airflow/dags/bd.py
[2023-10-14T04:54:39.386+0000] {logging_mixin.py:151} INFO - Error al conectar a la base de datos: connection to server at "localhost" (127.0.0.1), port 5432 failed: Connection refused
	Is the server running on that host and accepting TCP/IP connections?
connection to server at "localhost" (::1), port 5432 failed: Cannot assign requested address
	Is the server running on that host and accepting TCP/IP connections?
[2023-10-14T04:54:39.387+0000] {logging_mixin.py:151} INFO - Error al ejecutar la consulta: name 'connection' is not defined
[2023-10-14T04:54:39.398+0000] {logging_mixin.py:151} INFO - [2023-10-14T04:54:39.388+0000] {dagbag.py:347} ERROR - Failed to import: /opt/airflow/dags/bd.py
Traceback (most recent call last):
  File "/home/airflow/.local/lib/python3.8/site-packages/airflow/models/dagbag.py", line 343, in parse
    loader.exec_module(new_module)
  File "<frozen importlib._bootstrap_external>", line 843, in exec_module
  File "<frozen importlib._bootstrap>", line 219, in _call_with_frames_removed
  File "/opt/airflow/dags/bd.py", line 123, in <module>
    if connection:
NameError: name 'connection' is not defined
[2023-10-14T04:54:39.401+0000] {processor.py:841} WARNING - No viable dags retrieved from /opt/airflow/dags/bd.py
[2023-10-14T04:54:39.443+0000] {processor.py:179} INFO - Processing /opt/airflow/dags/bd.py took 0.522 seconds
[2023-10-14T04:55:09.886+0000] {processor.py:157} INFO - Started process (PID=128) to work on /opt/airflow/dags/bd.py
[2023-10-14T04:55:09.891+0000] {processor.py:829} INFO - Processing file /opt/airflow/dags/bd.py for tasks to queue
[2023-10-14T04:55:09.894+0000] {logging_mixin.py:151} INFO - [2023-10-14T04:55:09.894+0000] {dagbag.py:539} INFO - Filling up the DagBag from /opt/airflow/dags/bd.py
[2023-10-14T04:55:10.369+0000] {logging_mixin.py:151} INFO - Error al conectar a la base de datos: connection to server at "localhost" (127.0.0.1), port 5432 failed: Connection refused
	Is the server running on that host and accepting TCP/IP connections?
connection to server at "localhost" (::1), port 5432 failed: Cannot assign requested address
	Is the server running on that host and accepting TCP/IP connections?
[2023-10-14T04:55:10.370+0000] {logging_mixin.py:151} INFO - Error al ejecutar la consulta: name 'connection' is not defined
[2023-10-14T04:55:10.378+0000] {logging_mixin.py:151} INFO - [2023-10-14T04:55:10.371+0000] {dagbag.py:347} ERROR - Failed to import: /opt/airflow/dags/bd.py
Traceback (most recent call last):
  File "/home/airflow/.local/lib/python3.8/site-packages/airflow/models/dagbag.py", line 343, in parse
    loader.exec_module(new_module)
  File "<frozen importlib._bootstrap_external>", line 843, in exec_module
  File "<frozen importlib._bootstrap>", line 219, in _call_with_frames_removed
  File "/opt/airflow/dags/bd.py", line 123, in <module>
    if connection:
NameError: name 'connection' is not defined
[2023-10-14T04:55:10.380+0000] {processor.py:841} WARNING - No viable dags retrieved from /opt/airflow/dags/bd.py
[2023-10-14T04:55:10.411+0000] {processor.py:179} INFO - Processing /opt/airflow/dags/bd.py took 0.531 seconds
[2023-10-14T04:55:40.740+0000] {processor.py:157} INFO - Started process (PID=142) to work on /opt/airflow/dags/bd.py
[2023-10-14T04:55:40.741+0000] {processor.py:829} INFO - Processing file /opt/airflow/dags/bd.py for tasks to queue
[2023-10-14T04:55:40.743+0000] {logging_mixin.py:151} INFO - [2023-10-14T04:55:40.743+0000] {dagbag.py:539} INFO - Filling up the DagBag from /opt/airflow/dags/bd.py
[2023-10-14T04:55:44.372+0000] {logging_mixin.py:151} INFO - Error al conectar a la base de datos: connection to server at "localhost" (127.0.0.1), port 5432 failed: Connection refused
	Is the server running on that host and accepting TCP/IP connections?
connection to server at "localhost" (::1), port 5432 failed: Cannot assign requested address
	Is the server running on that host and accepting TCP/IP connections?
[2023-10-14T04:55:44.373+0000] {logging_mixin.py:151} INFO - Error al ejecutar la consulta: name 'connection' is not defined
[2023-10-14T04:55:44.392+0000] {logging_mixin.py:151} INFO - [2023-10-14T04:55:44.374+0000] {dagbag.py:347} ERROR - Failed to import: /opt/airflow/dags/bd.py
Traceback (most recent call last):
  File "/home/airflow/.local/lib/python3.8/site-packages/airflow/models/dagbag.py", line 343, in parse
    loader.exec_module(new_module)
  File "<frozen importlib._bootstrap_external>", line 843, in exec_module
  File "<frozen importlib._bootstrap>", line 219, in _call_with_frames_removed
  File "/opt/airflow/dags/bd.py", line 123, in <module>
    if connection:
NameError: name 'connection' is not defined
[2023-10-14T04:55:44.420+0000] {processor.py:841} WARNING - No viable dags retrieved from /opt/airflow/dags/bd.py
[2023-10-14T04:55:44.495+0000] {processor.py:179} INFO - Processing /opt/airflow/dags/bd.py took 3.760 seconds
[2023-10-14T04:56:14.846+0000] {processor.py:157} INFO - Started process (PID=156) to work on /opt/airflow/dags/bd.py
[2023-10-14T04:56:14.847+0000] {processor.py:829} INFO - Processing file /opt/airflow/dags/bd.py for tasks to queue
[2023-10-14T04:56:14.849+0000] {logging_mixin.py:151} INFO - [2023-10-14T04:56:14.848+0000] {dagbag.py:539} INFO - Filling up the DagBag from /opt/airflow/dags/bd.py
[2023-10-14T04:56:15.688+0000] {logging_mixin.py:151} INFO - Error al conectar a la base de datos: connection to server at "localhost" (127.0.0.1), port 5432 failed: Connection refused
	Is the server running on that host and accepting TCP/IP connections?
connection to server at "localhost" (::1), port 5432 failed: Cannot assign requested address
	Is the server running on that host and accepting TCP/IP connections?
[2023-10-14T04:56:15.689+0000] {logging_mixin.py:151} INFO - Error al ejecutar la consulta: name 'connection' is not defined
[2023-10-14T04:56:15.717+0000] {logging_mixin.py:151} INFO - [2023-10-14T04:56:15.691+0000] {dagbag.py:347} ERROR - Failed to import: /opt/airflow/dags/bd.py
Traceback (most recent call last):
  File "/home/airflow/.local/lib/python3.8/site-packages/airflow/models/dagbag.py", line 343, in parse
    loader.exec_module(new_module)
  File "<frozen importlib._bootstrap_external>", line 843, in exec_module
  File "<frozen importlib._bootstrap>", line 219, in _call_with_frames_removed
  File "/opt/airflow/dags/bd.py", line 123, in <module>
    if connection:
NameError: name 'connection' is not defined
[2023-10-14T04:56:15.720+0000] {processor.py:841} WARNING - No viable dags retrieved from /opt/airflow/dags/bd.py
[2023-10-14T04:56:15.794+0000] {processor.py:179} INFO - Processing /opt/airflow/dags/bd.py took 0.952 seconds
[2023-10-14T04:56:46.591+0000] {processor.py:157} INFO - Started process (PID=170) to work on /opt/airflow/dags/bd.py
[2023-10-14T04:56:46.591+0000] {processor.py:829} INFO - Processing file /opt/airflow/dags/bd.py for tasks to queue
[2023-10-14T04:56:46.593+0000] {logging_mixin.py:151} INFO - [2023-10-14T04:56:46.592+0000] {dagbag.py:539} INFO - Filling up the DagBag from /opt/airflow/dags/bd.py
[2023-10-14T04:56:47.089+0000] {logging_mixin.py:151} INFO - Error al conectar a la base de datos: connection to server at "localhost" (127.0.0.1), port 5432 failed: Connection refused
	Is the server running on that host and accepting TCP/IP connections?
connection to server at "localhost" (::1), port 5432 failed: Cannot assign requested address
	Is the server running on that host and accepting TCP/IP connections?
[2023-10-14T04:56:47.090+0000] {logging_mixin.py:151} INFO - Error al ejecutar la consulta: name 'connection' is not defined
[2023-10-14T04:56:47.097+0000] {logging_mixin.py:151} INFO - [2023-10-14T04:56:47.090+0000] {dagbag.py:347} ERROR - Failed to import: /opt/airflow/dags/bd.py
Traceback (most recent call last):
  File "/home/airflow/.local/lib/python3.8/site-packages/airflow/models/dagbag.py", line 343, in parse
    loader.exec_module(new_module)
  File "<frozen importlib._bootstrap_external>", line 843, in exec_module
  File "<frozen importlib._bootstrap>", line 219, in _call_with_frames_removed
  File "/opt/airflow/dags/bd.py", line 123, in <module>
    if connection:
NameError: name 'connection' is not defined
[2023-10-14T04:56:47.099+0000] {processor.py:841} WARNING - No viable dags retrieved from /opt/airflow/dags/bd.py
[2023-10-14T04:56:47.856+0000] {processor.py:179} INFO - Processing /opt/airflow/dags/bd.py took 1.270 seconds
[2023-10-14T04:57:18.439+0000] {processor.py:157} INFO - Started process (PID=184) to work on /opt/airflow/dags/bd.py
[2023-10-14T04:57:18.444+0000] {processor.py:829} INFO - Processing file /opt/airflow/dags/bd.py for tasks to queue
[2023-10-14T04:57:18.445+0000] {logging_mixin.py:151} INFO - [2023-10-14T04:57:18.445+0000] {dagbag.py:539} INFO - Filling up the DagBag from /opt/airflow/dags/bd.py
[2023-10-14T04:57:18.809+0000] {logging_mixin.py:151} INFO - Error al conectar a la base de datos: connection to server at "localhost" (127.0.0.1), port 5432 failed: Connection refused
	Is the server running on that host and accepting TCP/IP connections?
connection to server at "localhost" (::1), port 5432 failed: Cannot assign requested address
	Is the server running on that host and accepting TCP/IP connections?
[2023-10-14T04:57:18.810+0000] {logging_mixin.py:151} INFO - Error al ejecutar la consulta: name 'connection' is not defined
[2023-10-14T04:57:18.818+0000] {logging_mixin.py:151} INFO - [2023-10-14T04:57:18.811+0000] {dagbag.py:347} ERROR - Failed to import: /opt/airflow/dags/bd.py
Traceback (most recent call last):
  File "/home/airflow/.local/lib/python3.8/site-packages/airflow/models/dagbag.py", line 343, in parse
    loader.exec_module(new_module)
  File "<frozen importlib._bootstrap_external>", line 843, in exec_module
  File "<frozen importlib._bootstrap>", line 219, in _call_with_frames_removed
  File "/opt/airflow/dags/bd.py", line 123, in <module>
    if connection:
NameError: name 'connection' is not defined
[2023-10-14T04:57:18.820+0000] {processor.py:841} WARNING - No viable dags retrieved from /opt/airflow/dags/bd.py
[2023-10-14T04:57:18.852+0000] {processor.py:179} INFO - Processing /opt/airflow/dags/bd.py took 0.417 seconds
[2023-10-14T04:57:49.897+0000] {processor.py:157} INFO - Started process (PID=198) to work on /opt/airflow/dags/bd.py
[2023-10-14T04:57:49.898+0000] {processor.py:829} INFO - Processing file /opt/airflow/dags/bd.py for tasks to queue
[2023-10-14T04:57:49.900+0000] {logging_mixin.py:151} INFO - [2023-10-14T04:57:49.899+0000] {dagbag.py:539} INFO - Filling up the DagBag from /opt/airflow/dags/bd.py
[2023-10-14T04:57:50.289+0000] {logging_mixin.py:151} INFO - Error al conectar a la base de datos: connection to server at "localhost" (127.0.0.1), port 5432 failed: Connection refused
	Is the server running on that host and accepting TCP/IP connections?
connection to server at "localhost" (::1), port 5432 failed: Cannot assign requested address
	Is the server running on that host and accepting TCP/IP connections?
[2023-10-14T04:57:50.290+0000] {logging_mixin.py:151} INFO - Error al ejecutar la consulta: name 'connection' is not defined
[2023-10-14T04:57:50.297+0000] {logging_mixin.py:151} INFO - [2023-10-14T04:57:50.290+0000] {dagbag.py:347} ERROR - Failed to import: /opt/airflow/dags/bd.py
Traceback (most recent call last):
  File "/home/airflow/.local/lib/python3.8/site-packages/airflow/models/dagbag.py", line 343, in parse
    loader.exec_module(new_module)
  File "<frozen importlib._bootstrap_external>", line 843, in exec_module
  File "<frozen importlib._bootstrap>", line 219, in _call_with_frames_removed
  File "/opt/airflow/dags/bd.py", line 123, in <module>
    if connection:
NameError: name 'connection' is not defined
[2023-10-14T04:57:50.299+0000] {processor.py:841} WARNING - No viable dags retrieved from /opt/airflow/dags/bd.py
[2023-10-14T04:57:50.340+0000] {processor.py:179} INFO - Processing /opt/airflow/dags/bd.py took 0.447 seconds
[2023-10-14T04:58:20.452+0000] {processor.py:157} INFO - Started process (PID=212) to work on /opt/airflow/dags/bd.py
[2023-10-14T04:58:20.460+0000] {processor.py:829} INFO - Processing file /opt/airflow/dags/bd.py for tasks to queue
[2023-10-14T04:58:20.462+0000] {logging_mixin.py:151} INFO - [2023-10-14T04:58:20.462+0000] {dagbag.py:539} INFO - Filling up the DagBag from /opt/airflow/dags/bd.py
[2023-10-14T04:58:20.916+0000] {logging_mixin.py:151} INFO - Error al conectar a la base de datos: connection to server at "localhost" (127.0.0.1), port 5432 failed: Connection refused
	Is the server running on that host and accepting TCP/IP connections?
connection to server at "localhost" (::1), port 5432 failed: Cannot assign requested address
	Is the server running on that host and accepting TCP/IP connections?
[2023-10-14T04:58:20.917+0000] {logging_mixin.py:151} INFO - Error al ejecutar la consulta: name 'connection' is not defined
[2023-10-14T04:58:20.924+0000] {logging_mixin.py:151} INFO - [2023-10-14T04:58:20.917+0000] {dagbag.py:347} ERROR - Failed to import: /opt/airflow/dags/bd.py
Traceback (most recent call last):
  File "/home/airflow/.local/lib/python3.8/site-packages/airflow/models/dagbag.py", line 343, in parse
    loader.exec_module(new_module)
  File "<frozen importlib._bootstrap_external>", line 843, in exec_module
  File "<frozen importlib._bootstrap>", line 219, in _call_with_frames_removed
  File "/opt/airflow/dags/bd.py", line 123, in <module>
    if connection:
NameError: name 'connection' is not defined
[2023-10-14T04:58:20.926+0000] {processor.py:841} WARNING - No viable dags retrieved from /opt/airflow/dags/bd.py
[2023-10-14T04:58:20.959+0000] {processor.py:179} INFO - Processing /opt/airflow/dags/bd.py took 0.513 seconds
[2023-10-14T04:58:51.560+0000] {processor.py:157} INFO - Started process (PID=226) to work on /opt/airflow/dags/bd.py
[2023-10-14T04:58:51.565+0000] {processor.py:829} INFO - Processing file /opt/airflow/dags/bd.py for tasks to queue
[2023-10-14T04:58:51.566+0000] {logging_mixin.py:151} INFO - [2023-10-14T04:58:51.566+0000] {dagbag.py:539} INFO - Filling up the DagBag from /opt/airflow/dags/bd.py
[2023-10-14T04:58:51.961+0000] {logging_mixin.py:151} INFO - Error al conectar a la base de datos: connection to server at "localhost" (127.0.0.1), port 5432 failed: Connection refused
	Is the server running on that host and accepting TCP/IP connections?
connection to server at "localhost" (::1), port 5432 failed: Cannot assign requested address
	Is the server running on that host and accepting TCP/IP connections?
[2023-10-14T04:58:51.961+0000] {logging_mixin.py:151} INFO - Error al ejecutar la consulta: name 'connection' is not defined
[2023-10-14T04:58:51.970+0000] {logging_mixin.py:151} INFO - [2023-10-14T04:58:51.962+0000] {dagbag.py:347} ERROR - Failed to import: /opt/airflow/dags/bd.py
Traceback (most recent call last):
  File "/home/airflow/.local/lib/python3.8/site-packages/airflow/models/dagbag.py", line 343, in parse
    loader.exec_module(new_module)
  File "<frozen importlib._bootstrap_external>", line 843, in exec_module
  File "<frozen importlib._bootstrap>", line 219, in _call_with_frames_removed
  File "/opt/airflow/dags/bd.py", line 123, in <module>
    if connection:
NameError: name 'connection' is not defined
[2023-10-14T04:58:51.973+0000] {processor.py:841} WARNING - No viable dags retrieved from /opt/airflow/dags/bd.py
[2023-10-14T04:58:52.276+0000] {processor.py:179} INFO - Processing /opt/airflow/dags/bd.py took 0.720 seconds
[2023-10-14T04:59:23.010+0000] {processor.py:157} INFO - Started process (PID=240) to work on /opt/airflow/dags/bd.py
[2023-10-14T04:59:23.011+0000] {processor.py:829} INFO - Processing file /opt/airflow/dags/bd.py for tasks to queue
[2023-10-14T04:59:23.013+0000] {logging_mixin.py:151} INFO - [2023-10-14T04:59:23.012+0000] {dagbag.py:539} INFO - Filling up the DagBag from /opt/airflow/dags/bd.py
[2023-10-14T04:59:23.392+0000] {logging_mixin.py:151} INFO - Error al conectar a la base de datos: connection to server at "localhost" (127.0.0.1), port 5432 failed: Connection refused
	Is the server running on that host and accepting TCP/IP connections?
connection to server at "localhost" (::1), port 5432 failed: Cannot assign requested address
	Is the server running on that host and accepting TCP/IP connections?
[2023-10-14T04:59:23.393+0000] {logging_mixin.py:151} INFO - Error al ejecutar la consulta: name 'connection' is not defined
[2023-10-14T04:59:23.401+0000] {logging_mixin.py:151} INFO - [2023-10-14T04:59:23.394+0000] {dagbag.py:347} ERROR - Failed to import: /opt/airflow/dags/bd.py
Traceback (most recent call last):
  File "/home/airflow/.local/lib/python3.8/site-packages/airflow/models/dagbag.py", line 343, in parse
    loader.exec_module(new_module)
  File "<frozen importlib._bootstrap_external>", line 843, in exec_module
  File "<frozen importlib._bootstrap>", line 219, in _call_with_frames_removed
  File "/opt/airflow/dags/bd.py", line 123, in <module>
    if connection:
NameError: name 'connection' is not defined
[2023-10-14T04:59:23.403+0000] {processor.py:841} WARNING - No viable dags retrieved from /opt/airflow/dags/bd.py
[2023-10-14T04:59:23.437+0000] {processor.py:179} INFO - Processing /opt/airflow/dags/bd.py took 0.432 seconds
[2023-10-14T04:59:53.992+0000] {processor.py:157} INFO - Started process (PID=254) to work on /opt/airflow/dags/bd.py
[2023-10-14T04:59:53.993+0000] {processor.py:829} INFO - Processing file /opt/airflow/dags/bd.py for tasks to queue
[2023-10-14T04:59:53.994+0000] {logging_mixin.py:151} INFO - [2023-10-14T04:59:53.994+0000] {dagbag.py:539} INFO - Filling up the DagBag from /opt/airflow/dags/bd.py
[2023-10-14T04:59:54.511+0000] {logging_mixin.py:151} INFO - Error al conectar a la base de datos: connection to server at "localhost" (127.0.0.1), port 5432 failed: Connection refused
	Is the server running on that host and accepting TCP/IP connections?
connection to server at "localhost" (::1), port 5432 failed: Cannot assign requested address
	Is the server running on that host and accepting TCP/IP connections?
[2023-10-14T04:59:54.513+0000] {logging_mixin.py:151} INFO - Error al ejecutar la consulta: name 'connection' is not defined
[2023-10-14T04:59:54.587+0000] {logging_mixin.py:151} INFO - [2023-10-14T04:59:54.515+0000] {dagbag.py:347} ERROR - Failed to import: /opt/airflow/dags/bd.py
Traceback (most recent call last):
  File "/home/airflow/.local/lib/python3.8/site-packages/airflow/models/dagbag.py", line 343, in parse
    loader.exec_module(new_module)
  File "<frozen importlib._bootstrap_external>", line 843, in exec_module
  File "<frozen importlib._bootstrap>", line 219, in _call_with_frames_removed
  File "/opt/airflow/dags/bd.py", line 123, in <module>
    if connection:
NameError: name 'connection' is not defined
[2023-10-14T04:59:55.094+0000] {processor.py:841} WARNING - No viable dags retrieved from /opt/airflow/dags/bd.py
[2023-10-14T04:59:55.393+0000] {processor.py:179} INFO - Processing /opt/airflow/dags/bd.py took 1.404 seconds
[2023-10-14T05:00:25.754+0000] {processor.py:157} INFO - Started process (PID=268) to work on /opt/airflow/dags/bd.py
[2023-10-14T05:00:25.755+0000] {processor.py:829} INFO - Processing file /opt/airflow/dags/bd.py for tasks to queue
[2023-10-14T05:00:25.756+0000] {logging_mixin.py:151} INFO - [2023-10-14T05:00:25.755+0000] {dagbag.py:539} INFO - Filling up the DagBag from /opt/airflow/dags/bd.py
