[2023-10-14T14:09:25.120+0000] {taskinstance.py:1157} INFO - Dependencies all met for dep_context=non-requeueable deps ti=<TaskInstance: dag.read_csv manual__2023-10-14T14:08:22.205716+00:00 [queued]>
[2023-10-14T14:09:25.136+0000] {taskinstance.py:1157} INFO - Dependencies all met for dep_context=requeueable deps ti=<TaskInstance: dag.read_csv manual__2023-10-14T14:08:22.205716+00:00 [queued]>
[2023-10-14T14:09:25.136+0000] {taskinstance.py:1359} INFO - Starting attempt 2 of 2
[2023-10-14T14:09:25.164+0000] {taskinstance.py:1380} INFO - Executing <Task(PythonOperator): read_csv> on 2023-10-14 14:08:22.205716+00:00
[2023-10-14T14:09:25.169+0000] {standard_task_runner.py:57} INFO - Started process 166 to run task
[2023-10-14T14:09:25.182+0000] {standard_task_runner.py:84} INFO - Running: ['***', 'tasks', 'run', 'dag', 'read_csv', 'manual__2023-10-14T14:08:22.205716+00:00', '--job-id', '51', '--raw', '--subdir', 'DAGS_FOLDER/dag.py', '--cfg-path', '/tmp/tmpvch6691f']
[2023-10-14T14:09:25.194+0000] {standard_task_runner.py:85} INFO - Job 51: Subtask read_csv
[2023-10-14T14:09:25.295+0000] {task_command.py:415} INFO - Running <TaskInstance: dag.read_csv manual__2023-10-14T14:08:22.205716+00:00 [running]> on host e061e400a183
[2023-10-14T14:09:25.705+0000] {taskinstance.py:1660} INFO - Exporting env vars: AIRFLOW_CTX_DAG_EMAIL='***@example.com' AIRFLOW_CTX_DAG_OWNER='***' AIRFLOW_CTX_DAG_ID='dag' AIRFLOW_CTX_TASK_ID='read_csv' AIRFLOW_CTX_EXECUTION_DATE='2023-10-14T14:08:22.205716+00:00' AIRFLOW_CTX_TRY_NUMBER='2' AIRFLOW_CTX_DAG_RUN_ID='manual__2023-10-14T14:08:22.205716+00:00'
[2023-10-14T14:09:25.709+0000] {taskinstance.py:1935} ERROR - Task failed with exception
Traceback (most recent call last):
  File "/home/airflow/.local/lib/python3.8/site-packages/airflow/operators/python.py", line 192, in execute
    return_value = self.execute_callable()
  File "/home/airflow/.local/lib/python3.8/site-packages/airflow/operators/python.py", line 209, in execute_callable
    return self.python_callable(*self.op_args, **self.op_kwargs)
  File "/opt/airflow/dags/etl.py", line 10, in read_csv
    df = pd.read_csv("spotify_dataset.csv")
  File "/home/airflow/.local/lib/python3.8/site-packages/pandas/io/parsers/readers.py", line 912, in read_csv
    return _read(filepath_or_buffer, kwds)
  File "/home/airflow/.local/lib/python3.8/site-packages/pandas/io/parsers/readers.py", line 577, in _read
    parser = TextFileReader(filepath_or_buffer, **kwds)
  File "/home/airflow/.local/lib/python3.8/site-packages/pandas/io/parsers/readers.py", line 1407, in __init__
    self._engine = self._make_engine(f, self.engine)
  File "/home/airflow/.local/lib/python3.8/site-packages/pandas/io/parsers/readers.py", line 1661, in _make_engine
    self.handles = get_handle(
  File "/home/airflow/.local/lib/python3.8/site-packages/pandas/io/common.py", line 859, in get_handle
    handle = open(
FileNotFoundError: [Errno 2] No such file or directory: 'spotify_dataset.csv'
[2023-10-14T14:09:25.724+0000] {taskinstance.py:1398} INFO - Marking task as FAILED. dag_id=dag, task_id=read_csv, execution_date=20231014T140822, start_date=20231014T140925, end_date=20231014T140925
[2023-10-14T14:09:25.745+0000] {standard_task_runner.py:104} ERROR - Failed to execute job 51 for task read_csv ([Errno 2] No such file or directory: 'spotify_dataset.csv'; 166)
[2023-10-14T14:09:25.755+0000] {local_task_job_runner.py:228} INFO - Task exited with return code 1
[2023-10-14T14:09:25.777+0000] {taskinstance.py:2776} INFO - 0 downstream tasks scheduled from follow-on schedule check
