[2023-10-14T14:29:20.247+0000] {taskinstance.py:1157} INFO - Dependencies all met for dep_context=non-requeueable deps ti=<TaskInstance: dag.read_csv manual__2023-10-14T14:28:16.968014+00:00 [queued]>
[2023-10-14T14:29:20.255+0000] {taskinstance.py:1157} INFO - Dependencies all met for dep_context=requeueable deps ti=<TaskInstance: dag.read_csv manual__2023-10-14T14:28:16.968014+00:00 [queued]>
[2023-10-14T14:29:20.256+0000] {taskinstance.py:1359} INFO - Starting attempt 2 of 2
[2023-10-14T14:29:20.297+0000] {taskinstance.py:1380} INFO - Executing <Task(PythonOperator): read_csv> on 2023-10-14 14:28:16.968014+00:00
[2023-10-14T14:29:20.303+0000] {standard_task_runner.py:57} INFO - Started process 480 to run task
[2023-10-14T14:29:20.306+0000] {standard_task_runner.py:84} INFO - Running: ['***', 'tasks', 'run', 'dag', 'read_csv', 'manual__2023-10-14T14:28:16.968014+00:00', '--job-id', '57', '--raw', '--subdir', 'DAGS_FOLDER/dag.py', '--cfg-path', '/tmp/tmpc8462q5g']
[2023-10-14T14:29:20.309+0000] {standard_task_runner.py:85} INFO - Job 57: Subtask read_csv
[2023-10-14T14:29:20.365+0000] {task_command.py:415} INFO - Running <TaskInstance: dag.read_csv manual__2023-10-14T14:28:16.968014+00:00 [running]> on host e061e400a183
[2023-10-14T14:29:20.616+0000] {taskinstance.py:1660} INFO - Exporting env vars: AIRFLOW_CTX_DAG_EMAIL='***@example.com' AIRFLOW_CTX_DAG_OWNER='***' AIRFLOW_CTX_DAG_ID='dag' AIRFLOW_CTX_TASK_ID='read_csv' AIRFLOW_CTX_EXECUTION_DATE='2023-10-14T14:28:16.968014+00:00' AIRFLOW_CTX_TRY_NUMBER='2' AIRFLOW_CTX_DAG_RUN_ID='manual__2023-10-14T14:28:16.968014+00:00'
[2023-10-14T14:29:20.620+0000] {taskinstance.py:1935} ERROR - Task failed with exception
Traceback (most recent call last):
  File "/home/airflow/.local/lib/python3.8/site-packages/airflow/operators/python.py", line 192, in execute
    return_value = self.execute_callable()
  File "/home/airflow/.local/lib/python3.8/site-packages/airflow/operators/python.py", line 209, in execute_callable
    return self.python_callable(*self.op_args, **self.op_kwargs)
  File "/opt/airflow/dags/etl.py", line 10, in read_csv
    spotify_df = pd.read_csv("C:/Users/Guatavo/Documents/5toSemestre/airflow/dags/spotify_dataset.csv")
  File "/home/airflow/.local/lib/python3.8/site-packages/pandas/io/parsers/readers.py", line 912, in read_csv
    return _read(filepath_or_buffer, kwds)
  File "/home/airflow/.local/lib/python3.8/site-packages/pandas/io/parsers/readers.py", line 577, in _read
    parser = TextFileReader(filepath_or_buffer, **kwds)
  File "/home/airflow/.local/lib/python3.8/site-packages/pandas/io/parsers/readers.py", line 1407, in __init__
    self._engine = self._make_engine(f, self.engine)
  File "/home/airflow/.local/lib/python3.8/site-packages/pandas/io/parsers/readers.py", line 1661, in _make_engine
    self.handles = get_handle(
  File "/home/airflow/.local/lib/python3.8/site-packages/pandas/io/common.py", line 859, in get_handle
    handle = open(
FileNotFoundError: [Errno 2] No such file or directory: 'C:/Users/Guatavo/Documents/5toSemestre/airflow/dags/spotify_dataset.csv'
[2023-10-14T14:29:20.634+0000] {taskinstance.py:1398} INFO - Marking task as FAILED. dag_id=dag, task_id=read_csv, execution_date=20231014T142816, start_date=20231014T142920, end_date=20231014T142920
[2023-10-14T14:29:20.653+0000] {standard_task_runner.py:104} ERROR - Failed to execute job 57 for task read_csv ([Errno 2] No such file or directory: 'C:/Users/Guatavo/Documents/5toSemestre/airflow/dags/spotify_dataset.csv'; 480)
[2023-10-14T14:29:20.680+0000] {local_task_job_runner.py:228} INFO - Task exited with return code 1
[2023-10-14T14:29:20.701+0000] {taskinstance.py:2776} INFO - 0 downstream tasks scheduled from follow-on schedule check
