[2023-10-14T14:12:18.603+0000] {taskinstance.py:1157} INFO - Dependencies all met for dep_context=non-requeueable deps ti=<TaskInstance: dag.read_csv manual__2023-10-14T14:12:16.932596+00:00 [queued]>
[2023-10-14T14:12:18.618+0000] {taskinstance.py:1157} INFO - Dependencies all met for dep_context=requeueable deps ti=<TaskInstance: dag.read_csv manual__2023-10-14T14:12:16.932596+00:00 [queued]>
[2023-10-14T14:12:18.619+0000] {taskinstance.py:1359} INFO - Starting attempt 1 of 2
[2023-10-14T14:12:18.674+0000] {taskinstance.py:1380} INFO - Executing <Task(PythonOperator): read_csv> on 2023-10-14 14:12:16.932596+00:00
[2023-10-14T14:12:18.681+0000] {standard_task_runner.py:57} INFO - Started process 217 to run task
[2023-10-14T14:12:18.692+0000] {standard_task_runner.py:84} INFO - Running: ['***', 'tasks', 'run', 'dag', 'read_csv', 'manual__2023-10-14T14:12:16.932596+00:00', '--job-id', '52', '--raw', '--subdir', 'DAGS_FOLDER/dag.py', '--cfg-path', '/tmp/tmppl5m34zo']
[2023-10-14T14:12:18.704+0000] {standard_task_runner.py:85} INFO - Job 52: Subtask read_csv
[2023-10-14T14:12:18.947+0000] {task_command.py:415} INFO - Running <TaskInstance: dag.read_csv manual__2023-10-14T14:12:16.932596+00:00 [running]> on host e061e400a183
[2023-10-14T14:12:20.467+0000] {taskinstance.py:1660} INFO - Exporting env vars: AIRFLOW_CTX_DAG_EMAIL='***@example.com' AIRFLOW_CTX_DAG_OWNER='***' AIRFLOW_CTX_DAG_ID='dag' AIRFLOW_CTX_TASK_ID='read_csv' AIRFLOW_CTX_EXECUTION_DATE='2023-10-14T14:12:16.932596+00:00' AIRFLOW_CTX_TRY_NUMBER='1' AIRFLOW_CTX_DAG_RUN_ID='manual__2023-10-14T14:12:16.932596+00:00'
[2023-10-14T14:12:20.472+0000] {taskinstance.py:1935} ERROR - Task failed with exception
Traceback (most recent call last):
  File "/home/airflow/.local/lib/python3.8/site-packages/airflow/operators/python.py", line 192, in execute
    return_value = self.execute_callable()
  File "/home/airflow/.local/lib/python3.8/site-packages/airflow/operators/python.py", line 209, in execute_callable
    return self.python_callable(*self.op_args, **self.op_kwargs)
  File "/opt/airflow/dags/etl.py", line 10, in read_csv
    spotify_df = pd.read_csv("spotify_dataset.csv")
  File "/home/airflow/.local/lib/python3.8/site-packages/pandas/io/parsers/readers.py", line 912, in read_csv
    return _read(filepath_or_buffer, kwds)
  File "/home/airflow/.local/lib/python3.8/site-packages/pandas/io/parsers/readers.py", line 577, in _read
    parser = TextFileReader(filepath_or_buffer, **kwds)
  File "/home/airflow/.local/lib/python3.8/site-packages/pandas/io/parsers/readers.py", line 1407, in __init__
    self._engine = self._make_engine(f, self.engine)
  File "/home/airflow/.local/lib/python3.8/site-packages/pandas/io/parsers/readers.py", line 1661, in _make_engine
    self.handles = get_handle(
  File "/home/airflow/.local/lib/python3.8/site-packages/pandas/io/common.py", line 859, in get_handle
    handle = open(
FileNotFoundError: [Errno 2] No such file or directory: 'spotify_dataset.csv'
[2023-10-14T14:12:20.487+0000] {taskinstance.py:1398} INFO - Marking task as UP_FOR_RETRY. dag_id=dag, task_id=read_csv, execution_date=20231014T141216, start_date=20231014T141218, end_date=20231014T141220
[2023-10-14T14:12:20.506+0000] {standard_task_runner.py:104} ERROR - Failed to execute job 52 for task read_csv ([Errno 2] No such file or directory: 'spotify_dataset.csv'; 217)
[2023-10-14T14:12:20.557+0000] {local_task_job_runner.py:228} INFO - Task exited with return code 1
[2023-10-14T14:12:20.588+0000] {taskinstance.py:2776} INFO - 0 downstream tasks scheduled from follow-on schedule check
